Traceback (most recent call last):
  File "main.py", line 133, in <module>
    main(parser.parse_args()) 
  File "main.py", line 123, in main
    trainer.train(args.epochs, args.val_frequency, print_frequency=args.print_frequency, log_frequency=args.log_frequency, key=keyVal)
  File "/user/home/ee20947/cw/train.py", line 95, in train
    self.validate(self.val_loader, dataset, key , "Validation: ")
  File "/user/home/ee20947/cw/train.py", line 149, in validate
    accuracy = np.mean(evaluate(results["preds"], test_path, mode))
  File "/user/home/ee20947/cw/train.py", line 215, in evaluate
    labels.append(np.array(gts.iloc[i]['label']).astype(float))    # A 50D Ground Truth binary vector
  File "/mnt/storage/software/languages/anaconda/Anaconda3.8.8/lib/python3.8/site-packages/pandas/core/indexing.py", line 895, in __getitem__
    return self._getitem_axis(maybe_callable, axis=axis)
  File "/mnt/storage/software/languages/anaconda/Anaconda3.8.8/lib/python3.8/site-packages/pandas/core/indexing.py", line 1501, in _getitem_axis
    self._validate_integer(key, axis)
  File "/mnt/storage/software/languages/anaconda/Anaconda3.8.8/lib/python3.8/site-packages/pandas/core/indexing.py", line 1444, in _validate_integer
    raise IndexError("single positional indexer is out-of-bounds")
IndexError: single positional indexer is out-of-bounds
